<robot name="diff_robot">
    <link name="base_link">
    </link>
    <joint name="base_joint" type="fixed">
        <parent link="base_link"/>
        <child link="frame_link"/>
        <origin xyz="-0.1 0.0 0.0" rpy="0.0 0.0 0.0"/>
    </joint>
    <link name="frame_link">
        <visual>
            <geometry>
                <box size="0.2 0.15 0.07"/>
            </geometry>
            <origin xyz="0.1 0.0 0.035" rpy="0.0 0.0 0.0"/>
            <material name="white">
                <color rgba="1.0 0.0 0.0 1.0"/>
            </material>
        </visual>
        <inertial>
            <mass value="2.0"/>
            <origin xyz="0.1 0.0 0.035"/>
            <inertia ixx="0.1" ixy="0.0" ixz="0.0" iyy="0.1" iyz="0.0" izz="0.1"/>
        </inertial>
        <collision>
            <geometry>
                <box size="0.2 0.15 0.07"/>
            </geometry>
            <origin xyz="0.1 0.0 0.035" rpy="0.0 0.0 0.0"/>
        </collision>
    </link>
    <joint name="left_wheel_joint" type="continuous">
        <parent link="base_link"/>
        <child link="left_wheel_link"/>
        <origin xyz="-0.05 0.08 0.0" rpy="-1.57 0.0 0.0"/>
        <axis xyz="0.0 0.0 1.0"/>
    </joint>
    <link name="left_wheel_link">
        <visual>
            <geometry>
                <cylinder radius="0.03" length="0.015"/>
            </geometry>
            <origin xyz="0.0 0.0 0.0" rpy="0 0.0 0.0"/>
            <material name="blue">
                <color rgba="0.0 0.0 1.0 1.0"/>
            </material>
        </visual>
        <inertial>
            <mass value="0.5"/>
            <origin xyz="0.0 0.0 0.0"/>
            <inertia ixx="0.1" ixy="0.0" ixz="0.0" iyy="0.1" iyz="0.0" izz="0.1"/>
        </inertial>
        <collision>
            <geometry>
                <cylinder radius="0.03" length="0.015"/>
            </geometry>
            <origin xyz="0.0 0.0 0.0" rpy="0 0.0 0.0"/>
        </collision>
    </link>
    <joint name="right_wheel_joint" type="continuous">
        <parent link="base_link"/>
        <child link="right_wheel_link"/>
        <origin xyz="-0.05 -0.08 0.0" rpy="1.57 0.0 0.0"/>
        <axis xyz="0.0 0.0 1.0"/>
    </joint>
    <link name="right_wheel_link">
        <visual>
            <geometry>
                <cylinder radius="0.03" length="0.015"/>
            </geometry>
            <origin xyz="0.0 0.0 0.0" rpy="0 0.0 0.0"/>
            <material name="blue">
                <color rgba="0.0 0.0 1.0 1.0"/>
            </material>
        </visual>
        <inertial>
            <mass value="0.5"/>
            <origin xyz="0.0 0.0 0.0"/>
            <inertia ixx="0.1" ixy="0.0" ixz="0.0" iyy="0.1" iyz="0.0" izz="0.1"/>
        </inertial>
        <collision>
            <geometry>
                <cylinder radius="0.03" length="0.015"/>
            </geometry>
            <origin xyz="0.0 0.0 0.0" rpy="0 0.0 0.0"/>
        </collision>
    </link>
    <joint name="caster_joint" type="fixed">
        <parent link="base_link"/>
        <child link="caster_link"/>
        <origin xyz="0.05 0.0 0.0"/>
    </joint>
    <link name="caster_link">
        <visual>
            <geometry>
                <sphere radius="0.03"/>
            </geometry>
            <origin xyz="0.0 0.0 0.0"/>
            <material name="yellow">
                <color rgba="1.0 1.0 0.0 1.0"/>
            </material>
        </visual>
        <inertial>
            <mass value="1e-5"/>
            <origin xyz="0.0 0.0 0.0"/>
            <inertia ixx="1e-6" ixy="0" ixz="0" iyy="1e-6" iyz="0" izz="1e-6"/>
        </inertial>
        <collision>
            <geometry>
                <sphere radius="0.03"/>
            </geometry>
            <origin xyz="0.0 0.0 0.0"/>
        </collision>
    </link>

    <!-- Camera -->
    <link name="camera_link">
        <visual>
            <geometry>
                <box size="0.015 0.05 0.03"/>
            </geometry>
            <origin xyz="0.0 0.0 0.0"/>
            <material name="Purple">
                <color rgba="1.0 0.0 1.0 1.0"/>
            </material>
        </visual>
        <inertial>
            <mass value="1e-5" />
            <origin xyz="0 0 0" rpy="0 0 0"/>
            <inertia ixx="1e-6" ixy="0" ixz="0" iyy="1e-6" iyz="0" izz="1e-6" />
        </inertial>
        <collision>
            <geometry>
                <box size="0.015 0.05 0.03"/>
            </geometry>
            <origin xyz="0.0 0.0 0.0"/>
        </collision>
    </link>
    <joint name="camera_joint" type="fixed">
        <parent link="base_link"/>
        <child link="camera_link"/>
        <origin xyz="0.1 0.0 0.09" rpy="0.0 0.26 0.0"/>
    </joint>

    <!-- Hokuyo Laser -->
    <link name="hokuyo_link">
        <collision>
            <origin xyz="0 0 0" rpy="0 0 0"/>
            <geometry>
                <box size="0.1 0.1 0.1"/>
            </geometry>
        </collision>

        <visual>
            <origin xyz="0 0 0" rpy="0 0 0"/>
            <geometry>
                <!-- <cylinder radius="0.06" length="0.03"/> -->
                <mesh filename="package://my_robot/meshes/hokuyo.dae"/>
            </geometry>
        </visual>

        <inertial>
            <mass value="1e-5" />
            <origin xyz="0 0 0" rpy="0 0 0"/>
            <inertia ixx="1e-6" ixy="0" ixz="0" iyy="1e-6" iyz="0" izz="1e-6" />
        </inertial>
    </link>
    <joint name="hokuyo_joint" type="fixed">
        <axis xyz="0 1 0" />
        <origin xyz="0.0 0 0.11" rpy="0 0 0"/>
        <parent link="base_link"/>
        <child link="hokuyo_link"/>
    </joint>

    <!-- Transmission -->
    <transmission name="tran1">
        <type>transmission_interface/SimpleTransmission</type>
        <joint name="left_wheel_joint">
            <hardwareInterface>hardware_interface/VelocityJointInterface</hardwareInterface>
        </joint>
        <actuator name="motor1">
            <hardwareInterface>hardware_interface/VelocityJointInterface</hardwareInterface>
            <mechanicalReduction>10</mechanicalReduction>
        </actuator>
    </transmission>

    <transmission name="tran2">
        <type>transmission_interface/SimpleTransmission</type>
        <joint name="right_wheel_joint">
            <hardwareInterface>hardware_interface/VelocityJointInterface</hardwareInterface>
        </joint>
        <actuator name="motor2">
            <hardwareInterface>hardware_interface/VelocityJointInterface</hardwareInterface>
            <mechanicalReduction>10</mechanicalReduction>
        </actuator>
    </transmission>

    <!-- Gazebo -->
    <gazebo reference="frame_link">
        <material>Gazebo/Orange</material>
    </gazebo>
    <gazebo reference="left_wheel_link">
        <material>Gazebo/Blue</material>
    </gazebo>
    <gazebo reference="right_wheel_link">
        <material>Gazebo/Blue</material>
    </gazebo>
    <gazebo reference="caster_link">
        <material>Gazebo/Yellow</material>
        <mu1 value="0.001"/>
        <mu2 value="0.001"/>
    </gazebo>
    <!-- camera -->
    <gazebo reference="camera_link">
        <material>Gazebo/Purple</material>
        <sensor type="camera" name="camera1">
            <update_rate>30.0</update_rate>
            <camera name="head">
                <horizontal_fov>1.3962634</horizontal_fov>
                <image>
                    <width>800</width>
                    <height>800</height>
                    <format>R8G8B8</format>
                </image>
                <clip>
                    <near>0.02</near>
                    <far>300</far>
                </clip>
                <noise>
                    <type>gaussian</type>
                    <!-- Noise is sampled independently per pixel on each frame.
                    That pixel's noise value is added to each of its color
                    channels, which at that point lie in the range [0,1]. -->
                    <mean>0.0</mean>
                    <stddev>0.007</stddev>
                </noise>
            </camera>
            <plugin name="camera_controller" filename="libgazebo_ros_camera.so">
                <alwaysOn>true</alwaysOn>
                <updateRate>0.0</updateRate>
                <cameraName>my_robot/camera1</cameraName>
                <imageTopicName>image_raw</imageTopicName>
                <cameraInfoTopicName>camera_info</cameraInfoTopicName>
                <frameName>camera_link</frameName>
                <hackBaseline>0.07</hackBaseline>
                <distortionK1>0.0</distortionK1>
                <distortionK2>0.0</distortionK2>
                <distortionK3>0.0</distortionK3>
                <distortionT1>0.0</distortionT1>
                <distortionT2>0.0</distortionT2>
            </plugin>
        </sensor>
    </gazebo>

    <!-- hokuyo -->
    <gazebo reference="hokuyo_link">
        <sensor type="ray" name="head_hokuyo_sensor">
            <pose>0 0 0 0 0 0</pose>
            <visualize>false</visualize>
            <update_rate>40</update_rate>
            <ray>
                <scan>
                    <horizontal>
                        <samples>720</samples>
                        <resolution>1</resolution>
                        <min_angle>-3.1415926</min_angle>
                        <max_angle>3.1415926</max_angle>
                    </horizontal>
                </scan>
                <range>
                    <min>0.10</min>
                    <max>30.0</max>
                    <resolution>0.01</resolution>
                </range>
                <noise>
                    <type>gaussian</type>
                    <!-- Noise parameters based on published spec for Hokuyo laser
               achieving "+-30mm" accuracy at range < 10m.  A mean of 0.0m and
               stddev of 0.01m will put 99.7% of samples within 0.03m of the true
               reading. -->
                    <mean>0.0</mean>
                    <stddev>0.01</stddev>
                </noise>
            </ray>
            <plugin name="gazebo_ros_head_hokuyo_controller" filename="libgazebo_ros_laser.so">
                <topicName>/my_diffbot/laser/scan</topicName>
                <frameName>hokuyo_link</frameName>
            </plugin>
        </sensor>
    </gazebo>

    <gazebo>
        <plugin name="gazebo_ros_control" filename="libgazebo_ros_control.so">
            <robotNamespace>/my_diffbot</robotNamespace>
        </plugin>
    </gazebo>

</robot>